[2024-12-16T14:17:37.213+0000] {taskinstance.py:1159} INFO - Dependencies all met for dep_context=non-requeueable deps ti=<TaskInstance: All_Layer.clean_rating manual__2024-12-16T14:17:20.331942+00:00 [queued]>
[2024-12-16T14:17:37.275+0000] {taskinstance.py:1159} INFO - Dependencies all met for dep_context=requeueable deps ti=<TaskInstance: All_Layer.clean_rating manual__2024-12-16T14:17:20.331942+00:00 [queued]>
[2024-12-16T14:17:37.276+0000] {taskinstance.py:1361} INFO - Starting attempt 1 of 2
[2024-12-16T14:17:37.299+0000] {taskinstance.py:1382} INFO - Executing <Task(SparkSubmitOperator): clean_rating> on 2024-12-16 14:17:20.331942+00:00
[2024-12-16T14:17:37.313+0000] {standard_task_runner.py:57} INFO - Started process 662 to run task
[2024-12-16T14:17:37.316+0000] {standard_task_runner.py:84} INFO - Running: ['***', 'tasks', 'run', 'All_Layer', 'clean_rating', 'manual__2024-12-16T14:17:20.331942+00:00', '--job-id', '213', '--raw', '--subdir', 'DAGS_FOLDER/All_Offi.py', '--cfg-path', '/tmp/tmpbyzz5pzz']
[2024-12-16T14:17:37.323+0000] {standard_task_runner.py:85} INFO - Job 213: Subtask clean_rating
[2024-12-16T14:17:37.411+0000] {task_command.py:416} INFO - Running <TaskInstance: All_Layer.clean_rating manual__2024-12-16T14:17:20.331942+00:00 [running]> on host a2b73f6a4b3a
[2024-12-16T14:17:37.552+0000] {taskinstance.py:1662} INFO - Exporting env vars: AIRFLOW_CTX_DAG_OWNER='***' AIRFLOW_CTX_DAG_ID='All_Layer' AIRFLOW_CTX_TASK_ID='clean_rating' AIRFLOW_CTX_EXECUTION_DATE='2024-12-16T14:17:20.331942+00:00' AIRFLOW_CTX_TRY_NUMBER='1' AIRFLOW_CTX_DAG_RUN_ID='manual__2024-12-16T14:17:20.331942+00:00'
[2024-12-16T14:17:37.567+0000] {base.py:73} INFO - Using connection ID 'spark-conn' for task execution.
[2024-12-16T14:17:37.572+0000] {spark_submit.py:403} INFO - Spark-Submit cmd: spark-submit --master spark://spark-master:7077 --conf spark.sql.extensions=io.delta.sql.DeltaSparkSessionExtension --conf spark.sql.catalog.spark_catalog=org.apache.spark.sql.delta.catalog.DeltaCatalog --jars /opt/***/jars/hadoop-aws-3.3.4.jar,/opt/***/jars/s3-2.18.41.jar,/opt/***/jars/aws-java-sdk-1.12.367.jar,/opt/***/jars/delta-core_2.12-2.2.0.jar,/opt/***/jars/delta-storage-2.2.0.jar, --packages org.apache.hadoop:hadoop-aws:3.3.4 --num-executors 2 --total-executor-cores 2 --executor-cores 2 --executor-memory 1g --driver-memory 1g --name arrow-spark --deploy-mode client /opt/***/jobs/python/processing_rating.py s3a://lakehouse/bronze/ratings.parquet s3a://lakehouse/sliver/ratings
[2024-12-16T14:17:37.957+0000] {spark_submit.py:579} INFO - /home/***/.local/lib/python3.9/site-packages/pyspark/bin/load-spark-env.sh: line 68: ps: command not found
[2024-12-16T14:17:43.504+0000] {spark_submit.py:579} INFO - :: loading settings :: url = jar:file:/home/***/.local/lib/python3.9/site-packages/pyspark/jars/ivy-2.5.1.jar!/org/apache/ivy/core/settings/ivysettings.xml
[2024-12-16T14:17:43.847+0000] {spark_submit.py:579} INFO - Ivy Default Cache set to: /home/***/.ivy2/cache
[2024-12-16T14:17:43.853+0000] {spark_submit.py:579} INFO - The jars for the packages stored in: /home/***/.ivy2/jars
[2024-12-16T14:17:43.868+0000] {spark_submit.py:579} INFO - org.apache.hadoop#hadoop-aws added as a dependency
[2024-12-16T14:17:43.870+0000] {spark_submit.py:579} INFO - :: resolving dependencies :: org.apache.spark#spark-submit-parent-6c0ab4a8-f600-49fd-a2e2-b016cfec10fe;1.0
[2024-12-16T14:17:43.871+0000] {spark_submit.py:579} INFO - confs: [default]
[2024-12-16T14:17:44.508+0000] {spark_submit.py:579} INFO - found org.apache.hadoop#hadoop-aws;3.3.4 in spark-list
[2024-12-16T14:17:44.676+0000] {spark_submit.py:579} INFO - found com.amazonaws#aws-java-sdk-bundle;1.12.262 in central
[2024-12-16T14:17:44.718+0000] {spark_submit.py:579} INFO - found org.wildfly.openssl#wildfly-openssl;1.0.7.Final in spark-list
[2024-12-16T14:17:44.765+0000] {spark_submit.py:579} INFO - :: resolution report :: resolve 863ms :: artifacts dl 31ms
[2024-12-16T14:17:44.765+0000] {spark_submit.py:579} INFO - :: modules in use:
[2024-12-16T14:17:44.766+0000] {spark_submit.py:579} INFO - com.amazonaws#aws-java-sdk-bundle;1.12.262 from central in [default]
[2024-12-16T14:17:44.766+0000] {spark_submit.py:579} INFO - org.apache.hadoop#hadoop-aws;3.3.4 from spark-list in [default]
[2024-12-16T14:17:44.766+0000] {spark_submit.py:579} INFO - org.wildfly.openssl#wildfly-openssl;1.0.7.Final from spark-list in [default]
[2024-12-16T14:17:44.767+0000] {spark_submit.py:579} INFO - ---------------------------------------------------------------------
[2024-12-16T14:17:44.767+0000] {spark_submit.py:579} INFO - |                  |            modules            ||   artifacts   |
[2024-12-16T14:17:44.768+0000] {spark_submit.py:579} INFO - |       conf       | number| search|dwnlded|evicted|| number|dwnlded|
[2024-12-16T14:17:44.768+0000] {spark_submit.py:579} INFO - ---------------------------------------------------------------------
[2024-12-16T14:17:44.769+0000] {spark_submit.py:579} INFO - |      default     |   3   |   0   |   0   |   0   ||   3   |   0   |
[2024-12-16T14:17:44.770+0000] {spark_submit.py:579} INFO - ---------------------------------------------------------------------
[2024-12-16T14:17:44.773+0000] {spark_submit.py:579} INFO - :: retrieving :: org.apache.spark#spark-submit-parent-6c0ab4a8-f600-49fd-a2e2-b016cfec10fe
[2024-12-16T14:17:44.775+0000] {spark_submit.py:579} INFO - confs: [default]
[2024-12-16T14:17:44.785+0000] {spark_submit.py:579} INFO - 0 artifacts copied, 3 already retrieved (0kB/9ms)
[2024-12-16T14:17:45.562+0000] {spark_submit.py:579} INFO - 24/12/16 14:17:45 WARN NativeCodeLoader: Unable to load native-hadoop library for your platform... using builtin-java classes where applicable
[2024-12-16T14:17:47.790+0000] {spark_submit.py:579} INFO - 2024-12-16 14:17:47,790 INFO: Initializing Spark session...
[2024-12-16T14:17:48.101+0000] {spark_submit.py:579} INFO - 24/12/16 14:17:48 INFO SparkContext: Running Spark version 3.3.2
[2024-12-16T14:17:48.157+0000] {spark_submit.py:579} INFO - 24/12/16 14:17:48 INFO ResourceUtils: ==============================================================
[2024-12-16T14:17:48.159+0000] {spark_submit.py:579} INFO - 24/12/16 14:17:48 INFO ResourceUtils: No custom resources configured for spark.driver.
[2024-12-16T14:17:48.161+0000] {spark_submit.py:579} INFO - 24/12/16 14:17:48 INFO ResourceUtils: ==============================================================
[2024-12-16T14:17:48.162+0000] {spark_submit.py:579} INFO - 24/12/16 14:17:48 INFO SparkContext: Submitted application: CleanRatings
[2024-12-16T14:17:48.234+0000] {spark_submit.py:579} INFO - 24/12/16 14:17:48 INFO ResourceProfile: Default ResourceProfile created, executor resources: Map(cores -> name: cores, amount: 2, script: , vendor: , memory -> name: memory, amount: 1024, script: , vendor: , offHeap -> name: offHeap, amount: 0, script: , vendor: ), task resources: Map(cpus -> name: cpus, amount: 1.0)
[2024-12-16T14:17:48.262+0000] {spark_submit.py:579} INFO - 24/12/16 14:17:48 INFO ResourceProfile: Limiting resource is cpus at 2 tasks per executor
[2024-12-16T14:17:48.267+0000] {spark_submit.py:579} INFO - 24/12/16 14:17:48 INFO ResourceProfileManager: Added ResourceProfile id: 0
[2024-12-16T14:17:48.391+0000] {spark_submit.py:579} INFO - 24/12/16 14:17:48 INFO SecurityManager: Changing view acls to: ***
[2024-12-16T14:17:48.392+0000] {spark_submit.py:579} INFO - 24/12/16 14:17:48 INFO SecurityManager: Changing modify acls to: ***
[2024-12-16T14:17:48.394+0000] {spark_submit.py:579} INFO - 24/12/16 14:17:48 INFO SecurityManager: Changing view acls groups to:
[2024-12-16T14:17:48.398+0000] {spark_submit.py:579} INFO - 24/12/16 14:17:48 INFO SecurityManager: Changing modify acls groups to:
[2024-12-16T14:17:48.401+0000] {spark_submit.py:579} INFO - 24/12/16 14:17:48 INFO SecurityManager: SecurityManager: authentication disabled; ui acls disabled; users  with view permissions: Set(***); groups with view permissions: Set(); users  with modify permissions: Set(***); groups with modify permissions: Set()
[2024-12-16T14:17:49.322+0000] {spark_submit.py:579} INFO - 24/12/16 14:17:49 INFO Utils: Successfully started service 'sparkDriver' on port 38643.
[2024-12-16T14:17:49.366+0000] {spark_submit.py:579} INFO - 24/12/16 14:17:49 INFO SparkEnv: Registering MapOutputTracker
[2024-12-16T14:17:49.432+0000] {spark_submit.py:579} INFO - 24/12/16 14:17:49 INFO SparkEnv: Registering BlockManagerMaster
[2024-12-16T14:17:49.476+0000] {spark_submit.py:579} INFO - 24/12/16 14:17:49 INFO BlockManagerMasterEndpoint: Using org.apache.spark.storage.DefaultTopologyMapper for getting topology information
[2024-12-16T14:17:49.484+0000] {spark_submit.py:579} INFO - 24/12/16 14:17:49 INFO BlockManagerMasterEndpoint: BlockManagerMasterEndpoint up
[2024-12-16T14:17:49.495+0000] {spark_submit.py:579} INFO - 24/12/16 14:17:49 INFO SparkEnv: Registering BlockManagerMasterHeartbeat
[2024-12-16T14:17:49.577+0000] {spark_submit.py:579} INFO - 24/12/16 14:17:49 INFO DiskBlockManager: Created local directory at /tmp/blockmgr-3d4d83f9-3307-4b99-9269-a0ea47111619
[2024-12-16T14:17:49.627+0000] {spark_submit.py:579} INFO - 24/12/16 14:17:49 INFO MemoryStore: MemoryStore started with capacity 434.4 MiB
[2024-12-16T14:17:49.687+0000] {spark_submit.py:579} INFO - 24/12/16 14:17:49 INFO SparkEnv: Registering OutputCommitCoordinator
[2024-12-16T14:17:50.086+0000] {spark_submit.py:579} INFO - 24/12/16 14:17:50 WARN Utils: Service 'SparkUI' could not bind on port 4040. Attempting port 4041.
[2024-12-16T14:17:50.087+0000] {spark_submit.py:579} INFO - 24/12/16 14:17:50 WARN Utils: Service 'SparkUI' could not bind on port 4041. Attempting port 4042.
[2024-12-16T14:17:50.089+0000] {spark_submit.py:579} INFO - 24/12/16 14:17:50 WARN Utils: Service 'SparkUI' could not bind on port 4042. Attempting port 4043.
[2024-12-16T14:17:50.091+0000] {spark_submit.py:579} INFO - 24/12/16 14:17:50 WARN Utils: Service 'SparkUI' could not bind on port 4043. Attempting port 4044.
[2024-12-16T14:17:50.108+0000] {spark_submit.py:579} INFO - 24/12/16 14:17:50 INFO Utils: Successfully started service 'SparkUI' on port 4044.
[2024-12-16T14:17:50.237+0000] {spark_submit.py:579} INFO - 24/12/16 14:17:50 INFO SparkContext: Added JAR file:///opt/***/jars/hadoop-aws-3.3.4.jar at spark://a2b73f6a4b3a:38643/jars/hadoop-aws-3.3.4.jar with timestamp 1734358668086
[2024-12-16T14:17:50.242+0000] {spark_submit.py:579} INFO - 24/12/16 14:17:50 INFO SparkContext: Added JAR file:///opt/***/jars/s3-2.18.41.jar at spark://a2b73f6a4b3a:38643/jars/s3-2.18.41.jar with timestamp 1734358668086
[2024-12-16T14:17:50.244+0000] {spark_submit.py:579} INFO - 24/12/16 14:17:50 INFO SparkContext: Added JAR file:///opt/***/jars/aws-java-sdk-1.12.367.jar at spark://a2b73f6a4b3a:38643/jars/aws-java-sdk-1.12.367.jar with timestamp 1734358668086
[2024-12-16T14:17:50.258+0000] {spark_submit.py:579} INFO - 24/12/16 14:17:50 INFO SparkContext: Added JAR file:///opt/***/jars/delta-core_2.12-2.2.0.jar at spark://a2b73f6a4b3a:38643/jars/delta-core_2.12-2.2.0.jar with timestamp 1734358668086
[2024-12-16T14:17:50.260+0000] {spark_submit.py:579} INFO - 24/12/16 14:17:50 INFO SparkContext: Added JAR file:///opt/***/jars/delta-storage-2.2.0.jar at spark://a2b73f6a4b3a:38643/jars/delta-storage-2.2.0.jar with timestamp 1734358668086
[2024-12-16T14:17:50.261+0000] {spark_submit.py:579} INFO - 24/12/16 14:17:50 INFO SparkContext: Added JAR file:///home/***/.ivy2/jars/org.apache.hadoop_hadoop-aws-3.3.4.jar at spark://a2b73f6a4b3a:38643/jars/org.apache.hadoop_hadoop-aws-3.3.4.jar with timestamp 1734358668086
[2024-12-16T14:17:50.261+0000] {spark_submit.py:579} INFO - 24/12/16 14:17:50 INFO SparkContext: Added JAR file:///home/***/.ivy2/jars/com.amazonaws_aws-java-sdk-bundle-1.12.262.jar at spark://a2b73f6a4b3a:38643/jars/com.amazonaws_aws-java-sdk-bundle-1.12.262.jar with timestamp 1734358668086
[2024-12-16T14:17:50.262+0000] {spark_submit.py:579} INFO - 24/12/16 14:17:50 INFO SparkContext: Added JAR file:///home/***/.ivy2/jars/org.wildfly.openssl_wildfly-openssl-1.0.7.Final.jar at spark://a2b73f6a4b3a:38643/jars/org.wildfly.openssl_wildfly-openssl-1.0.7.Final.jar with timestamp 1734358668086
[2024-12-16T14:17:50.264+0000] {spark_submit.py:579} INFO - 24/12/16 14:17:50 INFO SparkContext: Added file file:///home/***/.ivy2/jars/org.apache.hadoop_hadoop-aws-3.3.4.jar at spark://a2b73f6a4b3a:38643/files/org.apache.hadoop_hadoop-aws-3.3.4.jar with timestamp 1734358668086
[2024-12-16T14:17:50.265+0000] {spark_submit.py:579} INFO - 24/12/16 14:17:50 INFO Utils: Copying /home/***/.ivy2/jars/org.apache.hadoop_hadoop-aws-3.3.4.jar to /tmp/spark-10c01962-ab61-4ba6-bb51-bca92e34f09b/userFiles-69df7617-b938-4198-a9a4-be87cd729bf1/org.apache.hadoop_hadoop-aws-3.3.4.jar
[2024-12-16T14:17:50.277+0000] {spark_submit.py:579} INFO - 24/12/16 14:17:50 INFO SparkContext: Added file file:///home/***/.ivy2/jars/com.amazonaws_aws-java-sdk-bundle-1.12.262.jar at spark://a2b73f6a4b3a:38643/files/com.amazonaws_aws-java-sdk-bundle-1.12.262.jar with timestamp 1734358668086
[2024-12-16T14:17:50.278+0000] {spark_submit.py:579} INFO - 24/12/16 14:17:50 INFO Utils: Copying /home/***/.ivy2/jars/com.amazonaws_aws-java-sdk-bundle-1.12.262.jar to /tmp/spark-10c01962-ab61-4ba6-bb51-bca92e34f09b/userFiles-69df7617-b938-4198-a9a4-be87cd729bf1/com.amazonaws_aws-java-sdk-bundle-1.12.262.jar
[2024-12-16T14:17:52.332+0000] {spark_submit.py:579} INFO - 24/12/16 14:17:52 INFO SparkContext: Added file file:///home/***/.ivy2/jars/org.wildfly.openssl_wildfly-openssl-1.0.7.Final.jar at spark://a2b73f6a4b3a:38643/files/org.wildfly.openssl_wildfly-openssl-1.0.7.Final.jar with timestamp 1734358668086
[2024-12-16T14:17:52.334+0000] {spark_submit.py:579} INFO - 24/12/16 14:17:52 INFO Utils: Copying /home/***/.ivy2/jars/org.wildfly.openssl_wildfly-openssl-1.0.7.Final.jar to /tmp/spark-10c01962-ab61-4ba6-bb51-bca92e34f09b/userFiles-69df7617-b938-4198-a9a4-be87cd729bf1/org.wildfly.openssl_wildfly-openssl-1.0.7.Final.jar
[2024-12-16T14:17:52.592+0000] {spark_submit.py:579} INFO - 24/12/16 14:17:52 INFO StandaloneAppClient$ClientEndpoint: Connecting to master spark://spark-master:7077...
[2024-12-16T14:17:52.698+0000] {spark_submit.py:579} INFO - 24/12/16 14:17:52 INFO TransportClientFactory: Successfully created connection to spark-master/172.18.0.5:7077 after 59 ms (0 ms spent in bootstraps)
[2024-12-16T14:17:54.072+0000] {spark_submit.py:579} INFO - 24/12/16 14:17:54 INFO StandaloneSchedulerBackend: Connected to Spark cluster with app ID app-20241216141754-0002
[2024-12-16T14:17:54.079+0000] {spark_submit.py:579} INFO - 24/12/16 14:17:54 INFO Utils: Successfully started service 'org.apache.spark.network.netty.NettyBlockTransferService' on port 34603.
[2024-12-16T14:17:54.080+0000] {spark_submit.py:579} INFO - 24/12/16 14:17:54 INFO NettyBlockTransferService: Server created on a2b73f6a4b3a:34603
[2024-12-16T14:17:54.083+0000] {spark_submit.py:579} INFO - 24/12/16 14:17:54 INFO BlockManager: Using org.apache.spark.storage.RandomBlockReplicationPolicy for block replication policy
[2024-12-16T14:17:54.093+0000] {spark_submit.py:579} INFO - 24/12/16 14:17:54 INFO BlockManagerMaster: Registering BlockManager BlockManagerId(driver, a2b73f6a4b3a, 34603, None)
[2024-12-16T14:17:54.101+0000] {spark_submit.py:579} INFO - 24/12/16 14:17:54 INFO BlockManagerMasterEndpoint: Registering block manager a2b73f6a4b3a:34603 with 434.4 MiB RAM, BlockManagerId(driver, a2b73f6a4b3a, 34603, None)
[2024-12-16T14:17:54.103+0000] {spark_submit.py:579} INFO - 24/12/16 14:17:54 INFO BlockManagerMaster: Registered BlockManager BlockManagerId(driver, a2b73f6a4b3a, 34603, None)
[2024-12-16T14:17:54.106+0000] {spark_submit.py:579} INFO - 24/12/16 14:17:54 INFO BlockManager: Initialized BlockManager: BlockManagerId(driver, a2b73f6a4b3a, 34603, None)
[2024-12-16T14:17:54.459+0000] {spark_submit.py:579} INFO - 24/12/16 14:17:54 INFO StandaloneSchedulerBackend: SchedulerBackend is ready for scheduling beginning after reached minRegisteredResourcesRatio: 0.0
[2024-12-16T14:17:55.044+0000] {spark_submit.py:579} INFO - 2024-12-16 14:17:55,044 INFO: Spark session initialized successfully.
[2024-12-16T14:17:55.045+0000] {spark_submit.py:579} INFO - 2024-12-16 14:17:55,044 INFO: Start cleaning ratings table
[2024-12-16T14:17:55.046+0000] {spark_submit.py:579} INFO - 2024-12-16 14:17:55,044 INFO: Reading data from s3a://lakehouse/bronze/ratings.parquet
[2024-12-16T14:17:55.057+0000] {spark_submit.py:579} INFO - 24/12/16 14:17:55 INFO SharedState: Setting hive.metastore.warehouse.dir ('null') to the value of spark.sql.warehouse.dir.
[2024-12-16T14:17:55.367+0000] {spark_submit.py:579} INFO - 24/12/16 14:17:55 WARN MetricsConfig: Cannot locate configuration: tried hadoop-metrics2-s3a-file-system.properties,hadoop-metrics2.properties
[2024-12-16T14:17:55.386+0000] {spark_submit.py:579} INFO - 24/12/16 14:17:55 INFO MetricsSystemImpl: Scheduled Metric snapshot period at 10 second(s).
[2024-12-16T14:17:55.387+0000] {spark_submit.py:579} INFO - 24/12/16 14:17:55 INFO MetricsSystemImpl: s3a-file-system metrics system started
[2024-12-16T14:17:57.808+0000] {spark_submit.py:579} INFO - 24/12/16 14:17:57 INFO SharedState: Warehouse path is 's3a://lakehouse/'.
[2024-12-16T14:18:00.853+0000] {spark_submit.py:579} INFO - 24/12/16 14:18:00 INFO InMemoryFileIndex: It took 238 ms to list leaf files for 1 paths.
[2024-12-16T14:18:01.886+0000] {spark_submit.py:579} INFO - 24/12/16 14:18:01 INFO SparkContext: Starting job: load at NativeMethodAccessorImpl.java:0
[2024-12-16T14:18:01.908+0000] {spark_submit.py:579} INFO - 24/12/16 14:18:01 INFO DAGScheduler: Got job 0 (load at NativeMethodAccessorImpl.java:0) with 1 output partitions
[2024-12-16T14:18:01.909+0000] {spark_submit.py:579} INFO - 24/12/16 14:18:01 INFO DAGScheduler: Final stage: ResultStage 0 (load at NativeMethodAccessorImpl.java:0)
[2024-12-16T14:18:01.910+0000] {spark_submit.py:579} INFO - 24/12/16 14:18:01 INFO DAGScheduler: Parents of final stage: List()
[2024-12-16T14:18:01.911+0000] {spark_submit.py:579} INFO - 24/12/16 14:18:01 INFO DAGScheduler: Missing parents: List()
[2024-12-16T14:18:01.937+0000] {spark_submit.py:579} INFO - 24/12/16 14:18:01 INFO DAGScheduler: Submitting ResultStage 0 (MapPartitionsRDD[1] at load at NativeMethodAccessorImpl.java:0), which has no missing parents
[2024-12-16T14:18:02.106+0000] {spark_submit.py:579} INFO - 24/12/16 14:18:02 INFO MemoryStore: Block broadcast_0 stored as values in memory (estimated size 106.2 KiB, free 434.3 MiB)
[2024-12-16T14:18:02.197+0000] {spark_submit.py:579} INFO - 24/12/16 14:18:02 INFO MemoryStore: Block broadcast_0_piece0 stored as bytes in memory (estimated size 38.3 KiB, free 434.3 MiB)
[2024-12-16T14:18:02.220+0000] {spark_submit.py:579} INFO - 24/12/16 14:18:02 INFO BlockManagerInfo: Added broadcast_0_piece0 in memory on a2b73f6a4b3a:34603 (size: 38.3 KiB, free: 434.4 MiB)
[2024-12-16T14:18:02.225+0000] {spark_submit.py:579} INFO - 24/12/16 14:18:02 INFO SparkContext: Created broadcast 0 from broadcast at DAGScheduler.scala:1513
[2024-12-16T14:18:02.270+0000] {spark_submit.py:579} INFO - 24/12/16 14:18:02 INFO DAGScheduler: Submitting 1 missing tasks from ResultStage 0 (MapPartitionsRDD[1] at load at NativeMethodAccessorImpl.java:0) (first 15 tasks are for partitions Vector(0))
[2024-12-16T14:18:02.272+0000] {spark_submit.py:579} INFO - 24/12/16 14:18:02 INFO TaskSchedulerImpl: Adding task set 0.0 with 1 tasks resource profile 0
[2024-12-16T14:18:17.322+0000] {spark_submit.py:579} INFO - 24/12/16 14:18:17 WARN TaskSchedulerImpl: Initial job has not accepted any resources; check your cluster UI to ensure that workers are registered and have sufficient resources
[2024-12-16T14:18:32.322+0000] {spark_submit.py:579} INFO - 24/12/16 14:18:32 WARN TaskSchedulerImpl: Initial job has not accepted any resources; check your cluster UI to ensure that workers are registered and have sufficient resources
[2024-12-16T14:18:47.322+0000] {spark_submit.py:579} INFO - 24/12/16 14:18:47 WARN TaskSchedulerImpl: Initial job has not accepted any resources; check your cluster UI to ensure that workers are registered and have sufficient resources
[2024-12-16T14:19:02.321+0000] {spark_submit.py:579} INFO - 24/12/16 14:19:02 WARN TaskSchedulerImpl: Initial job has not accepted any resources; check your cluster UI to ensure that workers are registered and have sufficient resources
[2024-12-16T14:19:21.203+0000] {spark_submit.py:579} INFO - 24/12/16 14:19:17 WARN TaskSchedulerImpl: Initial job has not accepted any resources; check your cluster UI to ensure that workers are registered and have sufficient resources
[2024-12-16T14:19:22.446+0000] {job.py:219} ERROR - Job heartbeat got an exception
Traceback (most recent call last):
  File "/home/airflow/.local/lib/python3.9/site-packages/sqlalchemy/engine/base.py", line 3371, in _wrap_pool_connect
    return fn()
  File "/home/airflow/.local/lib/python3.9/site-packages/sqlalchemy/pool/base.py", line 327, in connect
    return _ConnectionFairy._checkout(self)
  File "/home/airflow/.local/lib/python3.9/site-packages/sqlalchemy/pool/base.py", line 894, in _checkout
    fairy = _ConnectionRecord.checkout(pool)
  File "/home/airflow/.local/lib/python3.9/site-packages/sqlalchemy/pool/base.py", line 493, in checkout
    rec = pool._do_get()
  File "/home/airflow/.local/lib/python3.9/site-packages/sqlalchemy/pool/impl.py", line 256, in _do_get
    return self._create_connection()
  File "/home/airflow/.local/lib/python3.9/site-packages/sqlalchemy/pool/base.py", line 273, in _create_connection
    return _ConnectionRecord(self)
  File "/home/airflow/.local/lib/python3.9/site-packages/sqlalchemy/pool/base.py", line 388, in __init__
    self.__connect()
  File "/home/airflow/.local/lib/python3.9/site-packages/sqlalchemy/pool/base.py", line 691, in __connect
    pool.logger.debug("Error on connect(): %s", e)
  File "/home/airflow/.local/lib/python3.9/site-packages/sqlalchemy/util/langhelpers.py", line 70, in __exit__
    compat.raise_(
  File "/home/airflow/.local/lib/python3.9/site-packages/sqlalchemy/util/compat.py", line 211, in raise_
    raise exception
  File "/home/airflow/.local/lib/python3.9/site-packages/sqlalchemy/pool/base.py", line 686, in __connect
    self.dbapi_connection = connection = pool._invoke_creator(self)
  File "/home/airflow/.local/lib/python3.9/site-packages/sqlalchemy/engine/create.py", line 574, in connect
    return dialect.connect(*cargs, **cparams)
  File "/home/airflow/.local/lib/python3.9/site-packages/sqlalchemy/engine/default.py", line 598, in connect
    return self.dbapi.connect(*cargs, **cparams)
  File "/home/airflow/.local/lib/python3.9/site-packages/psycopg2/__init__.py", line 122, in connect
    conn = _connect(dsn, connection_factory=connection_factory, **kwasync)
psycopg2.OperationalError: could not translate host name "postgres" to address: Temporary failure in name resolution


The above exception was the direct cause of the following exception:

Traceback (most recent call last):
  File "/home/airflow/.local/lib/python3.9/site-packages/airflow/jobs/job.py", line 190, in heartbeat
    session.merge(self)
  File "/home/airflow/.local/lib/python3.9/site-packages/sqlalchemy/orm/session.py", line 3056, in merge
    return self._merge(
  File "/home/airflow/.local/lib/python3.9/site-packages/sqlalchemy/orm/session.py", line 3136, in _merge
    merged = self.get(
  File "/home/airflow/.local/lib/python3.9/site-packages/sqlalchemy/orm/session.py", line 2853, in get
    return self._get_impl(
  File "/home/airflow/.local/lib/python3.9/site-packages/sqlalchemy/orm/session.py", line 2975, in _get_impl
    return db_load_fn(
  File "/home/airflow/.local/lib/python3.9/site-packages/sqlalchemy/orm/loading.py", line 530, in load_on_pk_identity
    session.execute(
  File "/home/airflow/.local/lib/python3.9/site-packages/sqlalchemy/orm/session.py", line 1716, in execute
    conn = self._connection_for_bind(bind)
  File "/home/airflow/.local/lib/python3.9/site-packages/sqlalchemy/orm/session.py", line 1555, in _connection_for_bind
    return self._transaction._connection_for_bind(
  File "/home/airflow/.local/lib/python3.9/site-packages/sqlalchemy/orm/session.py", line 750, in _connection_for_bind
    conn = bind.connect()
  File "/home/airflow/.local/lib/python3.9/site-packages/sqlalchemy/future/engine.py", line 406, in connect
    return super(Engine, self).connect()
  File "/home/airflow/.local/lib/python3.9/site-packages/sqlalchemy/engine/base.py", line 3325, in connect
    return self._connection_cls(self, close_with_result=close_with_result)
  File "/home/airflow/.local/lib/python3.9/site-packages/sqlalchemy/engine/base.py", line 96, in __init__
    else engine.raw_connection()
  File "/home/airflow/.local/lib/python3.9/site-packages/sqlalchemy/engine/base.py", line 3404, in raw_connection
    return self._wrap_pool_connect(self.pool.connect, _connection)
  File "/home/airflow/.local/lib/python3.9/site-packages/sqlalchemy/engine/base.py", line 3374, in _wrap_pool_connect
    Connection._handle_dbapi_exception_noconnection(
  File "/home/airflow/.local/lib/python3.9/site-packages/sqlalchemy/engine/base.py", line 2208, in _handle_dbapi_exception_noconnection
    util.raise_(
  File "/home/airflow/.local/lib/python3.9/site-packages/sqlalchemy/util/compat.py", line 211, in raise_
    raise exception
  File "/home/airflow/.local/lib/python3.9/site-packages/sqlalchemy/engine/base.py", line 3371, in _wrap_pool_connect
    return fn()
  File "/home/airflow/.local/lib/python3.9/site-packages/sqlalchemy/pool/base.py", line 327, in connect
    return _ConnectionFairy._checkout(self)
  File "/home/airflow/.local/lib/python3.9/site-packages/sqlalchemy/pool/base.py", line 894, in _checkout
    fairy = _ConnectionRecord.checkout(pool)
  File "/home/airflow/.local/lib/python3.9/site-packages/sqlalchemy/pool/base.py", line 493, in checkout
    rec = pool._do_get()
  File "/home/airflow/.local/lib/python3.9/site-packages/sqlalchemy/pool/impl.py", line 256, in _do_get
    return self._create_connection()
  File "/home/airflow/.local/lib/python3.9/site-packages/sqlalchemy/pool/base.py", line 273, in _create_connection
    return _ConnectionRecord(self)
  File "/home/airflow/.local/lib/python3.9/site-packages/sqlalchemy/pool/base.py", line 388, in __init__
    self.__connect()
  File "/home/airflow/.local/lib/python3.9/site-packages/sqlalchemy/pool/base.py", line 691, in __connect
    pool.logger.debug("Error on connect(): %s", e)
  File "/home/airflow/.local/lib/python3.9/site-packages/sqlalchemy/util/langhelpers.py", line 70, in __exit__
    compat.raise_(
  File "/home/airflow/.local/lib/python3.9/site-packages/sqlalchemy/util/compat.py", line 211, in raise_
    raise exception
  File "/home/airflow/.local/lib/python3.9/site-packages/sqlalchemy/pool/base.py", line 686, in __connect
    self.dbapi_connection = connection = pool._invoke_creator(self)
  File "/home/airflow/.local/lib/python3.9/site-packages/sqlalchemy/engine/create.py", line 574, in connect
    return dialect.connect(*cargs, **cparams)
  File "/home/airflow/.local/lib/python3.9/site-packages/sqlalchemy/engine/default.py", line 598, in connect
    return self.dbapi.connect(*cargs, **cparams)
  File "/home/airflow/.local/lib/python3.9/site-packages/psycopg2/__init__.py", line 122, in connect
    conn = _connect(dsn, connection_factory=connection_factory, **kwasync)
sqlalchemy.exc.OperationalError: (psycopg2.OperationalError) could not translate host name "postgres" to address: Temporary failure in name resolution

(Background on this error at: https://sqlalche.me/e/14/e3q8)
[2024-12-16T14:19:37.761+0000] {spark_submit.py:579} INFO - 24/12/16 14:19:33 WARN TaskSchedulerImpl: Initial job has not accepted any resources; check your cluster UI to ensure that workers are registered and have sufficient resources
[2024-12-16T14:19:50.807+0000] {spark_submit.py:579} INFO - 24/12/16 14:19:47 WARN TaskSchedulerImpl: Initial job has not accepted any resources; check your cluster UI to ensure that workers are registered and have sufficient resources
[2024-12-16T14:20:03.811+0000] {spark_submit.py:579} INFO - 24/12/16 14:20:03 WARN TaskSchedulerImpl: Initial job has not accepted any resources; check your cluster UI to ensure that workers are registered and have sufficient resources
[2024-12-16T14:19:55.107+0000] {job.py:219} ERROR - Job heartbeat got an exception
Traceback (most recent call last):
  File "/home/airflow/.local/lib/python3.9/site-packages/sqlalchemy/engine/base.py", line 3371, in _wrap_pool_connect
    return fn()
  File "/home/airflow/.local/lib/python3.9/site-packages/sqlalchemy/pool/base.py", line 327, in connect
    return _ConnectionFairy._checkout(self)
  File "/home/airflow/.local/lib/python3.9/site-packages/sqlalchemy/pool/base.py", line 894, in _checkout
    fairy = _ConnectionRecord.checkout(pool)
  File "/home/airflow/.local/lib/python3.9/site-packages/sqlalchemy/pool/base.py", line 493, in checkout
    rec = pool._do_get()
  File "/home/airflow/.local/lib/python3.9/site-packages/sqlalchemy/pool/impl.py", line 256, in _do_get
    return self._create_connection()
  File "/home/airflow/.local/lib/python3.9/site-packages/sqlalchemy/pool/base.py", line 273, in _create_connection
    return _ConnectionRecord(self)
  File "/home/airflow/.local/lib/python3.9/site-packages/sqlalchemy/pool/base.py", line 388, in __init__
    self.__connect()
  File "/home/airflow/.local/lib/python3.9/site-packages/sqlalchemy/pool/base.py", line 691, in __connect
    pool.logger.debug("Error on connect(): %s", e)
  File "/home/airflow/.local/lib/python3.9/site-packages/sqlalchemy/util/langhelpers.py", line 70, in __exit__
    compat.raise_(
  File "/home/airflow/.local/lib/python3.9/site-packages/sqlalchemy/util/compat.py", line 211, in raise_
    raise exception
  File "/home/airflow/.local/lib/python3.9/site-packages/sqlalchemy/pool/base.py", line 686, in __connect
    self.dbapi_connection = connection = pool._invoke_creator(self)
  File "/home/airflow/.local/lib/python3.9/site-packages/sqlalchemy/engine/create.py", line 574, in connect
    return dialect.connect(*cargs, **cparams)
  File "/home/airflow/.local/lib/python3.9/site-packages/sqlalchemy/engine/default.py", line 598, in connect
    return self.dbapi.connect(*cargs, **cparams)
  File "/home/airflow/.local/lib/python3.9/site-packages/psycopg2/__init__.py", line 122, in connect
    conn = _connect(dsn, connection_factory=connection_factory, **kwasync)
psycopg2.OperationalError: could not translate host name "postgres" to address: Temporary failure in name resolution


The above exception was the direct cause of the following exception:

Traceback (most recent call last):
  File "/home/airflow/.local/lib/python3.9/site-packages/airflow/jobs/job.py", line 190, in heartbeat
    session.merge(self)
  File "/home/airflow/.local/lib/python3.9/site-packages/sqlalchemy/orm/session.py", line 3056, in merge
    return self._merge(
  File "/home/airflow/.local/lib/python3.9/site-packages/sqlalchemy/orm/session.py", line 3136, in _merge
    merged = self.get(
  File "/home/airflow/.local/lib/python3.9/site-packages/sqlalchemy/orm/session.py", line 2853, in get
    return self._get_impl(
  File "/home/airflow/.local/lib/python3.9/site-packages/sqlalchemy/orm/session.py", line 2975, in _get_impl
    return db_load_fn(
  File "/home/airflow/.local/lib/python3.9/site-packages/sqlalchemy/orm/loading.py", line 530, in load_on_pk_identity
    session.execute(
  File "/home/airflow/.local/lib/python3.9/site-packages/sqlalchemy/orm/session.py", line 1716, in execute
    conn = self._connection_for_bind(bind)
  File "/home/airflow/.local/lib/python3.9/site-packages/sqlalchemy/orm/session.py", line 1555, in _connection_for_bind
    return self._transaction._connection_for_bind(
  File "/home/airflow/.local/lib/python3.9/site-packages/sqlalchemy/orm/session.py", line 750, in _connection_for_bind
    conn = bind.connect()
  File "/home/airflow/.local/lib/python3.9/site-packages/sqlalchemy/future/engine.py", line 406, in connect
    return super(Engine, self).connect()
  File "/home/airflow/.local/lib/python3.9/site-packages/sqlalchemy/engine/base.py", line 3325, in connect
    return self._connection_cls(self, close_with_result=close_with_result)
  File "/home/airflow/.local/lib/python3.9/site-packages/sqlalchemy/engine/base.py", line 96, in __init__
    else engine.raw_connection()
  File "/home/airflow/.local/lib/python3.9/site-packages/sqlalchemy/engine/base.py", line 3404, in raw_connection
    return self._wrap_pool_connect(self.pool.connect, _connection)
  File "/home/airflow/.local/lib/python3.9/site-packages/sqlalchemy/engine/base.py", line 3374, in _wrap_pool_connect
    Connection._handle_dbapi_exception_noconnection(
  File "/home/airflow/.local/lib/python3.9/site-packages/sqlalchemy/engine/base.py", line 2208, in _handle_dbapi_exception_noconnection
    util.raise_(
  File "/home/airflow/.local/lib/python3.9/site-packages/sqlalchemy/util/compat.py", line 211, in raise_
    raise exception
  File "/home/airflow/.local/lib/python3.9/site-packages/sqlalchemy/engine/base.py", line 3371, in _wrap_pool_connect
    return fn()
  File "/home/airflow/.local/lib/python3.9/site-packages/sqlalchemy/pool/base.py", line 327, in connect
    return _ConnectionFairy._checkout(self)
  File "/home/airflow/.local/lib/python3.9/site-packages/sqlalchemy/pool/base.py", line 894, in _checkout
    fairy = _ConnectionRecord.checkout(pool)
  File "/home/airflow/.local/lib/python3.9/site-packages/sqlalchemy/pool/base.py", line 493, in checkout
    rec = pool._do_get()
  File "/home/airflow/.local/lib/python3.9/site-packages/sqlalchemy/pool/impl.py", line 256, in _do_get
    return self._create_connection()
  File "/home/airflow/.local/lib/python3.9/site-packages/sqlalchemy/pool/base.py", line 273, in _create_connection
    return _ConnectionRecord(self)
  File "/home/airflow/.local/lib/python3.9/site-packages/sqlalchemy/pool/base.py", line 388, in __init__
    self.__connect()
  File "/home/airflow/.local/lib/python3.9/site-packages/sqlalchemy/pool/base.py", line 691, in __connect
    pool.logger.debug("Error on connect(): %s", e)
  File "/home/airflow/.local/lib/python3.9/site-packages/sqlalchemy/util/langhelpers.py", line 70, in __exit__
    compat.raise_(
  File "/home/airflow/.local/lib/python3.9/site-packages/sqlalchemy/util/compat.py", line 211, in raise_
    raise exception
  File "/home/airflow/.local/lib/python3.9/site-packages/sqlalchemy/pool/base.py", line 686, in __connect
    self.dbapi_connection = connection = pool._invoke_creator(self)
  File "/home/airflow/.local/lib/python3.9/site-packages/sqlalchemy/engine/create.py", line 574, in connect
    return dialect.connect(*cargs, **cparams)
  File "/home/airflow/.local/lib/python3.9/site-packages/sqlalchemy/engine/default.py", line 598, in connect
    return self.dbapi.connect(*cargs, **cparams)
  File "/home/airflow/.local/lib/python3.9/site-packages/psycopg2/__init__.py", line 122, in connect
    conn = _connect(dsn, connection_factory=connection_factory, **kwasync)
sqlalchemy.exc.OperationalError: (psycopg2.OperationalError) could not translate host name "postgres" to address: Temporary failure in name resolution

(Background on this error at: https://sqlalche.me/e/14/e3q8)
[2024-12-16T14:20:14.634+0000] {local_task_job_runner.py:294} WARNING - State of this instance has been externally set to restarting. Terminating instance.
[2024-12-16T14:20:14.649+0000] {process_utils.py:131} INFO - Sending 15 to group 662. PIDs of all processes in the group: [667, 960, 662]
[2024-12-16T14:20:14.661+0000] {process_utils.py:86} INFO - Sending the signal 15 to group 662
[2024-12-16T14:20:14.670+0000] {taskinstance.py:1632} ERROR - Received SIGTERM. Terminating subprocesses.
[2024-12-16T14:20:14.678+0000] {spark_submit.py:705} INFO - Sending kill signal to spark-submit
[2024-12-16T14:20:15.011+0000] {process_utils.py:79} INFO - Process psutil.Process(pid=960, status='terminated', started='14:17:46') (960) terminated with exit code None
[2024-12-16T14:20:15.448+0000] {taskinstance.py:1937} ERROR - Task failed with exception
Traceback (most recent call last):
  File "/home/airflow/.local/lib/python3.9/site-packages/airflow/providers/apache/spark/operators/spark_submit.py", line 174, in execute
    self._hook.submit(self.application)
  File "/home/airflow/.local/lib/python3.9/site-packages/airflow/providers/apache/spark/hooks/spark_submit.py", line 493, in submit
    self._process_spark_submit_log(iter(self._submit_sp.stdout))  # type: ignore
  File "/home/airflow/.local/lib/python3.9/site-packages/airflow/providers/apache/spark/hooks/spark_submit.py", line 542, in _process_spark_submit_log
    for line in itr:
  File "/home/airflow/.local/lib/python3.9/site-packages/airflow/models/taskinstance.py", line 1634, in signal_handler
    raise AirflowException("Task received SIGTERM signal")
airflow.exceptions.AirflowException: Task received SIGTERM signal
[2024-12-16T14:20:15.510+0000] {taskinstance.py:1400} INFO - Marking task as UP_FOR_RETRY. dag_id=All_Layer, task_id=clean_rating, execution_date=20241216T141720, start_date=20241216T141737, end_date=20241216T142015
[2024-12-16T14:20:15.886+0000] {standard_task_runner.py:104} ERROR - Failed to execute job 213 for task clean_rating (Task received SIGTERM signal; 662)
[2024-12-16T14:20:15.913+0000] {process_utils.py:79} INFO - Process psutil.Process(pid=662, status='terminated', exitcode=1, started='14:17:37') (662) terminated with exit code 1
[2024-12-16T14:20:15.914+0000] {process_utils.py:79} INFO - Process psutil.Process(pid=667, status='terminated', started='14:17:37') (667) terminated with exit code None
