[2024-10-04T01:41:20.986+0000] {taskinstance.py:1157} INFO - Dependencies all met for dep_context=non-requeueable deps ti=<TaskInstance: bronze_layer_processing.bronze_keywords manual__2024-10-04T01:36:16.073299+00:00 [queued]>
[2024-10-04T01:41:20.997+0000] {taskinstance.py:1157} INFO - Dependencies all met for dep_context=requeueable deps ti=<TaskInstance: bronze_layer_processing.bronze_keywords manual__2024-10-04T01:36:16.073299+00:00 [queued]>
[2024-10-04T01:41:20.998+0000] {taskinstance.py:1359} INFO - Starting attempt 2 of 2
[2024-10-04T01:41:21.014+0000] {taskinstance.py:1380} INFO - Executing <Task(PythonOperator): bronze_keywords> on 2024-10-04 01:36:16.073299+00:00
[2024-10-04T01:41:21.025+0000] {standard_task_runner.py:57} INFO - Started process 769 to run task
[2024-10-04T01:41:21.033+0000] {standard_task_runner.py:84} INFO - Running: ['***', 'tasks', 'run', 'bronze_layer_processing', 'bronze_keywords', 'manual__2024-10-04T01:36:16.073299+00:00', '--job-id', '4', '--raw', '--subdir', 'DAGS_FOLDER/bronze_layer.py', '--cfg-path', '/tmp/tmprz16ilje']
[2024-10-04T01:41:21.039+0000] {standard_task_runner.py:85} INFO - Job 4: Subtask bronze_keywords
[2024-10-04T01:41:21.134+0000] {task_command.py:415} INFO - Running <TaskInstance: bronze_layer_processing.bronze_keywords manual__2024-10-04T01:36:16.073299+00:00 [running]> on host 928e276d789d
[2024-10-04T01:41:21.259+0000] {taskinstance.py:1660} INFO - Exporting env vars: AIRFLOW_CTX_DAG_OWNER='***' AIRFLOW_CTX_DAG_ID='bronze_layer_processing' AIRFLOW_CTX_TASK_ID='bronze_keywords' AIRFLOW_CTX_EXECUTION_DATE='2024-10-04T01:36:16.073299+00:00' AIRFLOW_CTX_TRY_NUMBER='2' AIRFLOW_CTX_DAG_RUN_ID='manual__2024-10-04T01:36:16.073299+00:00'
[2024-10-04T01:41:21.823+0000] {taskinstance.py:1935} ERROR - Task failed with exception
Traceback (most recent call last):
  File "/home/airflow/.local/lib/python3.11/site-packages/airflow/operators/python.py", line 192, in execute
    return_value = self.execute_callable()
                   ^^^^^^^^^^^^^^^^^^^^^^^
  File "/home/airflow/.local/lib/python3.11/site-packages/airflow/operators/python.py", line 209, in execute_callable
    return self.python_callable(*self.op_args, **self.op_kwargs)
           ^^^^^^^^^^^^^^^^^^^^^^^^^^^^^^^^^^^^^^^^^^^^^^^^^^^^^
  File "/opt/airflow/dags/bronze_layer.py", line 38, in bronze_keywords
    df = get_data_from_raw('keywords')
         ^^^^^^^^^^^^^^^^^^^^^^^^^^^^^
  File "/opt/airflow/dags/bronze_layer.py", line 25, in get_data_from_raw
    response = client.get_object(Bucket="lakehouse", Key=f'raw/{name}.csv')
               ^^^^^^^^^^^^^^^^^^^^^^^^^^^^^^^^^^^^^^^^^^^^^^^^^^^^^^^^^^^^
  File "/home/airflow/.local/lib/python3.11/site-packages/botocore/client.py", line 535, in _api_call
    return self._make_api_call(operation_name, kwargs)
           ^^^^^^^^^^^^^^^^^^^^^^^^^^^^^^^^^^^^^^^^^^^
  File "/home/airflow/.local/lib/python3.11/site-packages/botocore/client.py", line 980, in _make_api_call
    raise error_class(parsed_response, operation_name)
botocore.exceptions.ClientError: An error occurred (InvalidAccessKeyId) when calling the GetObject operation: The Access Key Id you provided does not exist in our records.
[2024-10-04T01:41:21.839+0000] {taskinstance.py:1398} INFO - Marking task as FAILED. dag_id=bronze_layer_processing, task_id=bronze_keywords, execution_date=20241004T013616, start_date=20241004T014120, end_date=20241004T014121
[2024-10-04T01:41:21.852+0000] {standard_task_runner.py:104} ERROR - Failed to execute job 4 for task bronze_keywords (An error occurred (InvalidAccessKeyId) when calling the GetObject operation: The Access Key Id you provided does not exist in our records.; 769)
[2024-10-04T01:41:21.889+0000] {local_task_job_runner.py:228} INFO - Task exited with return code 1
[2024-10-04T01:41:21.916+0000] {taskinstance.py:2776} INFO - 0 downstream tasks scheduled from follow-on schedule check
