[2024-11-14T14:37:25.971+0000] {taskinstance.py:1159} INFO - Dependencies all met for dep_context=non-requeueable deps ti=<TaskInstance: test_flowwww.credits_cleaned scheduled__2024-11-13T00:00:00+00:00 [queued]>
[2024-11-14T14:37:25.985+0000] {taskinstance.py:1159} INFO - Dependencies all met for dep_context=requeueable deps ti=<TaskInstance: test_flowwww.credits_cleaned scheduled__2024-11-13T00:00:00+00:00 [queued]>
[2024-11-14T14:37:25.986+0000] {taskinstance.py:1361} INFO - Starting attempt 2 of 2
[2024-11-14T14:37:26.008+0000] {taskinstance.py:1382} INFO - Executing <Task(SparkSubmitOperator): credits_cleaned> on 2024-11-13 00:00:00+00:00
[2024-11-14T14:37:26.013+0000] {standard_task_runner.py:57} INFO - Started process 221 to run task
[2024-11-14T14:37:26.015+0000] {standard_task_runner.py:84} INFO - Running: ['***', 'tasks', 'run', 'test_flowwww', 'credits_cleaned', 'scheduled__2024-11-13T00:00:00+00:00', '--job-id', '248', '--raw', '--subdir', 'DAGS_FOLDER/test_flow.py', '--cfg-path', '/tmp/tmp9tqh2xd3']
[2024-11-14T14:37:26.018+0000] {standard_task_runner.py:85} INFO - Job 248: Subtask credits_cleaned
[2024-11-14T14:37:26.069+0000] {task_command.py:416} INFO - Running <TaskInstance: test_flowwww.credits_cleaned scheduled__2024-11-13T00:00:00+00:00 [running]> on host 7ea45ba85247
[2024-11-14T14:37:26.177+0000] {taskinstance.py:1662} INFO - Exporting env vars: AIRFLOW_CTX_DAG_OWNER='***' AIRFLOW_CTX_DAG_ID='test_flowwww' AIRFLOW_CTX_TASK_ID='credits_cleaned' AIRFLOW_CTX_EXECUTION_DATE='2024-11-13T00:00:00+00:00' AIRFLOW_CTX_TRY_NUMBER='2' AIRFLOW_CTX_DAG_RUN_ID='scheduled__2024-11-13T00:00:00+00:00'
[2024-11-14T14:37:26.187+0000] {base.py:73} INFO - Using connection ID 'spark-conn' for task execution.
[2024-11-14T14:37:26.189+0000] {spark_submit.py:403} INFO - Spark-Submit cmd: spark-submit --master spark://spark-master:7077 --conf spark.sql.extensions=io.delta.sql.DeltaSparkSessionExtension --conf spark.sql.catalog.spark_catalog=org.apache.spark.sql.delta.catalog.DeltaCatalog --jars /opt/***/jars/hadoop-aws-3.3.4.jar,/opt/***/jars/s3-2.18.41.jar,/opt/***/jars/aws-java-sdk-1.12.367.jar,/opt/***/jars/delta-core_2.12-2.2.0.jar,/opt/***/jars/delta-storage-2.2.0.jar, --packages org.apache.hadoop:hadoop-aws:3.3.4 --num-executors 2 --total-executor-cores 2 --executor-cores 2 --executor-memory 2g --driver-memory 1g --name arrow-spark --deploy-mode client /opt/***/jobs/python/test_Credit.py s3a://lakehouse/bronze/credits.parquet s3a://lakehouse/sliver/credit
[2024-11-14T14:37:26.375+0000] {spark_submit.py:579} INFO - /home/***/.local/lib/python3.9/site-packages/pyspark/bin/load-spark-env.sh: line 68: ps: command not found
[2024-11-14T14:37:28.944+0000] {spark_submit.py:579} INFO - :: loading settings :: url = jar:file:/home/***/.local/lib/python3.9/site-packages/pyspark/jars/ivy-2.5.1.jar!/org/apache/ivy/core/settings/ivysettings.xml
[2024-11-14T14:37:29.136+0000] {spark_submit.py:579} INFO - Ivy Default Cache set to: /home/***/.ivy2/cache
[2024-11-14T14:37:29.136+0000] {spark_submit.py:579} INFO - The jars for the packages stored in: /home/***/.ivy2/jars
[2024-11-14T14:37:29.142+0000] {spark_submit.py:579} INFO - org.apache.hadoop#hadoop-aws added as a dependency
[2024-11-14T14:37:29.144+0000] {spark_submit.py:579} INFO - :: resolving dependencies :: org.apache.spark#spark-submit-parent-be1274fe-854c-4f10-a7bb-627a7ecdd258;1.0
[2024-11-14T14:37:29.144+0000] {spark_submit.py:579} INFO - confs: [default]
[2024-11-14T14:37:34.901+0000] {spark_submit.py:579} INFO - found org.apache.hadoop#hadoop-aws;3.3.4 in central
[2024-11-14T14:37:36.953+0000] {spark_submit.py:579} INFO - found com.amazonaws#aws-java-sdk-bundle;1.12.262 in central
[2024-11-14T14:37:42.527+0000] {spark_submit.py:579} INFO - found org.wildfly.openssl#wildfly-openssl;1.0.7.Final in central
[2024-11-14T14:37:42.763+0000] {spark_submit.py:579} INFO - downloading https://repo1.maven.org/maven2/org/apache/hadoop/hadoop-aws/3.3.4/hadoop-aws-3.3.4.jar ...
[2024-11-14T14:37:46.421+0000] {spark_submit.py:579} INFO - [SUCCESSFUL ] org.apache.hadoop#hadoop-aws;3.3.4!hadoop-aws.jar (3882ms)
[2024-11-14T14:37:46.655+0000] {spark_submit.py:579} INFO - downloading https://repo1.maven.org/maven2/com/amazonaws/aws-java-sdk-bundle/1.12.262/aws-java-sdk-bundle-1.12.262.jar ...
[2024-11-14T14:38:36.477+0000] {job.py:219} ERROR - Job heartbeat got an exception
Traceback (most recent call last):
  File "/home/airflow/.local/lib/python3.9/site-packages/sqlalchemy/engine/base.py", line 3371, in _wrap_pool_connect
    return fn()
  File "/home/airflow/.local/lib/python3.9/site-packages/sqlalchemy/pool/base.py", line 327, in connect
    return _ConnectionFairy._checkout(self)
  File "/home/airflow/.local/lib/python3.9/site-packages/sqlalchemy/pool/base.py", line 894, in _checkout
    fairy = _ConnectionRecord.checkout(pool)
  File "/home/airflow/.local/lib/python3.9/site-packages/sqlalchemy/pool/base.py", line 493, in checkout
    rec = pool._do_get()
  File "/home/airflow/.local/lib/python3.9/site-packages/sqlalchemy/pool/impl.py", line 256, in _do_get
    return self._create_connection()
  File "/home/airflow/.local/lib/python3.9/site-packages/sqlalchemy/pool/base.py", line 273, in _create_connection
    return _ConnectionRecord(self)
  File "/home/airflow/.local/lib/python3.9/site-packages/sqlalchemy/pool/base.py", line 388, in __init__
    self.__connect()
  File "/home/airflow/.local/lib/python3.9/site-packages/sqlalchemy/pool/base.py", line 691, in __connect
    pool.logger.debug("Error on connect(): %s", e)
  File "/home/airflow/.local/lib/python3.9/site-packages/sqlalchemy/util/langhelpers.py", line 70, in __exit__
    compat.raise_(
  File "/home/airflow/.local/lib/python3.9/site-packages/sqlalchemy/util/compat.py", line 211, in raise_
    raise exception
  File "/home/airflow/.local/lib/python3.9/site-packages/sqlalchemy/pool/base.py", line 686, in __connect
    self.dbapi_connection = connection = pool._invoke_creator(self)
  File "/home/airflow/.local/lib/python3.9/site-packages/sqlalchemy/engine/create.py", line 574, in connect
    return dialect.connect(*cargs, **cparams)
  File "/home/airflow/.local/lib/python3.9/site-packages/sqlalchemy/engine/default.py", line 598, in connect
    return self.dbapi.connect(*cargs, **cparams)
  File "/home/airflow/.local/lib/python3.9/site-packages/psycopg2/__init__.py", line 122, in connect
    conn = _connect(dsn, connection_factory=connection_factory, **kwasync)
psycopg2.OperationalError: could not translate host name "postgres" to address: Temporary failure in name resolution


The above exception was the direct cause of the following exception:

Traceback (most recent call last):
  File "/home/airflow/.local/lib/python3.9/site-packages/airflow/jobs/job.py", line 190, in heartbeat
    session.merge(self)
  File "/home/airflow/.local/lib/python3.9/site-packages/sqlalchemy/orm/session.py", line 3056, in merge
    return self._merge(
  File "/home/airflow/.local/lib/python3.9/site-packages/sqlalchemy/orm/session.py", line 3136, in _merge
    merged = self.get(
  File "/home/airflow/.local/lib/python3.9/site-packages/sqlalchemy/orm/session.py", line 2853, in get
    return self._get_impl(
  File "/home/airflow/.local/lib/python3.9/site-packages/sqlalchemy/orm/session.py", line 2975, in _get_impl
    return db_load_fn(
  File "/home/airflow/.local/lib/python3.9/site-packages/sqlalchemy/orm/loading.py", line 530, in load_on_pk_identity
    session.execute(
  File "/home/airflow/.local/lib/python3.9/site-packages/sqlalchemy/orm/session.py", line 1716, in execute
    conn = self._connection_for_bind(bind)
  File "/home/airflow/.local/lib/python3.9/site-packages/sqlalchemy/orm/session.py", line 1555, in _connection_for_bind
    return self._transaction._connection_for_bind(
  File "/home/airflow/.local/lib/python3.9/site-packages/sqlalchemy/orm/session.py", line 750, in _connection_for_bind
    conn = bind.connect()
  File "/home/airflow/.local/lib/python3.9/site-packages/sqlalchemy/future/engine.py", line 406, in connect
    return super(Engine, self).connect()
  File "/home/airflow/.local/lib/python3.9/site-packages/sqlalchemy/engine/base.py", line 3325, in connect
    return self._connection_cls(self, close_with_result=close_with_result)
  File "/home/airflow/.local/lib/python3.9/site-packages/sqlalchemy/engine/base.py", line 96, in __init__
    else engine.raw_connection()
  File "/home/airflow/.local/lib/python3.9/site-packages/sqlalchemy/engine/base.py", line 3404, in raw_connection
    return self._wrap_pool_connect(self.pool.connect, _connection)
  File "/home/airflow/.local/lib/python3.9/site-packages/sqlalchemy/engine/base.py", line 3374, in _wrap_pool_connect
    Connection._handle_dbapi_exception_noconnection(
  File "/home/airflow/.local/lib/python3.9/site-packages/sqlalchemy/engine/base.py", line 2208, in _handle_dbapi_exception_noconnection
    util.raise_(
  File "/home/airflow/.local/lib/python3.9/site-packages/sqlalchemy/util/compat.py", line 211, in raise_
    raise exception
  File "/home/airflow/.local/lib/python3.9/site-packages/sqlalchemy/engine/base.py", line 3371, in _wrap_pool_connect
    return fn()
  File "/home/airflow/.local/lib/python3.9/site-packages/sqlalchemy/pool/base.py", line 327, in connect
    return _ConnectionFairy._checkout(self)
  File "/home/airflow/.local/lib/python3.9/site-packages/sqlalchemy/pool/base.py", line 894, in _checkout
    fairy = _ConnectionRecord.checkout(pool)
  File "/home/airflow/.local/lib/python3.9/site-packages/sqlalchemy/pool/base.py", line 493, in checkout
    rec = pool._do_get()
  File "/home/airflow/.local/lib/python3.9/site-packages/sqlalchemy/pool/impl.py", line 256, in _do_get
    return self._create_connection()
  File "/home/airflow/.local/lib/python3.9/site-packages/sqlalchemy/pool/base.py", line 273, in _create_connection
    return _ConnectionRecord(self)
  File "/home/airflow/.local/lib/python3.9/site-packages/sqlalchemy/pool/base.py", line 388, in __init__
    self.__connect()
  File "/home/airflow/.local/lib/python3.9/site-packages/sqlalchemy/pool/base.py", line 691, in __connect
    pool.logger.debug("Error on connect(): %s", e)
  File "/home/airflow/.local/lib/python3.9/site-packages/sqlalchemy/util/langhelpers.py", line 70, in __exit__
    compat.raise_(
  File "/home/airflow/.local/lib/python3.9/site-packages/sqlalchemy/util/compat.py", line 211, in raise_
    raise exception
  File "/home/airflow/.local/lib/python3.9/site-packages/sqlalchemy/pool/base.py", line 686, in __connect
    self.dbapi_connection = connection = pool._invoke_creator(self)
  File "/home/airflow/.local/lib/python3.9/site-packages/sqlalchemy/engine/create.py", line 574, in connect
    return dialect.connect(*cargs, **cparams)
  File "/home/airflow/.local/lib/python3.9/site-packages/sqlalchemy/engine/default.py", line 598, in connect
    return self.dbapi.connect(*cargs, **cparams)
  File "/home/airflow/.local/lib/python3.9/site-packages/psycopg2/__init__.py", line 122, in connect
    conn = _connect(dsn, connection_factory=connection_factory, **kwasync)
sqlalchemy.exc.OperationalError: (psycopg2.OperationalError) could not translate host name "postgres" to address: Temporary failure in name resolution

(Background on this error at: https://sqlalche.me/e/14/e3q8)
[2024-11-14T14:39:32.605+0000] {local_task_job_runner.py:294} WARNING - State of this instance has been externally set to failed. Terminating instance.
[2024-11-14T14:39:32.622+0000] {process_utils.py:131} INFO - Sending 15 to group 221. PIDs of all processes in the group: [235, 221]
[2024-11-14T14:39:32.629+0000] {process_utils.py:86} INFO - Sending the signal 15 to group 221
[2024-11-14T14:39:32.678+0000] {taskinstance.py:1632} ERROR - Received SIGTERM. Terminating subprocesses.
[2024-11-14T14:39:32.805+0000] {process_utils.py:79} INFO - Process psutil.Process(pid=235, status='terminated', started='14:37:25') (235) terminated with exit code None
[2024-11-14T14:39:33.881+0000] {process_utils.py:79} INFO - Process psutil.Process(pid=221, status='terminated', exitcode=0, started='14:37:25') (221) terminated with exit code 0
